Workbook

Sheet 總表
A1: 項次 | B1: 縣市 | C1: 114年度 | F1: 115年度 | I1: 114、115差異統計 | L1: 說明
C2: 號誌控制器總數 | D2: 連線號誌數 | E2: 整體連線率 | F2: 號誌控制器總數 | G2: 連線號誌數 | H2: 整體連線率 | I2: 號誌控制器總數 | J2: 連線號誌數 | K2: 整體連線率
A3: 1 | B3: 基隆市 | C3: 302 | D3: 105 | E3: =D3/C3 -> 0.34768212 | F3: =COUNTA('清冊(基隆市)'!F:F)-1 -> 168 | G3: =COUNTIF('清冊(基隆市)'!F:F,"有") -> 87 | H3: =G3/F3 -> 0.51785714 | I3: =F3-C3 -> -134 | J3: =G3-D3 -> -18 | K3: =H3-E3 -> 0.17017502
A4: 2 | B4: 臺北市 | C4: 2723 | D4: 2690 | E4: =D4/C4 -> 0.98788101 | F4: =COUNTA('清冊(臺北市)'!F:F)-1 -> 2468 | G4: =COUNTIF('清冊(臺北市)'!F:F,"有") -> 2468 | H4: =G4/F4 -> 1 | I4: =F4-C4 -> -255 | J4: =G4-D4 -> -222 | K4: =H4-E4 -> 0.012118986
A5: 3 | B5: 新北市 | C5: 4087 | D5: 2877 | E5: =D5/C5 -> 0.70393932 | F5: =COUNTA('清冊(新北市)'!F:F)-1 -> 3792 | G5: =COUNTIF('清冊(新北市)'!F:F,"有") -> 3792 | H5: =G5/F5 -> 1 | I5: =F5-C5 -> -295 | J5: =G5-D5 -> 915 | K5: =H5-E5 -> 0.29606068
A6: 4 | B6: 桃園市 | C6: 3453 | D6: 2351 | E6: =D6/C6 -> 0.68085723 | F6: =COUNTA('清冊(新北市)'!F:F)-1 -> 3792 | G6: =COUNTIF('清冊(桃園市)'!F:F,"有") -> 1991 | H6: =G6/F6 -> 0.52505274 | I6: =F6-C6 -> 339 | J6: =G6-D6 -> -360 | K6: =H6-E6 -> -0.15580448
A7: 5 | B7: 新竹縣 | C7: 928 | D7: 511 | E7: =D7/C7 -> 0.55064655 | F7: =COUNTA('清冊(新竹縣)'!F:F)-1 -> 783 | G7: =COUNTIF('清冊(新竹縣)'!F:F,"有") -> 120 | H7: =G7/F7 -> 0.1532567 | I7: =F7-C7 -> -145 | J7: =G7-D7 -> -391 | K7: =H7-E7 -> -0.39738985
A8: 6 | B8: 新竹市 | C8: 552 | D8: 505 | E8: =D8/C8 -> 0.91485507 | F8: =COUNTA('清冊(新竹市)'!F:F)-1 -> 439 | G8: =COUNTIF('清冊(新竹市)'!F:F,"有") -> 411 | H8: =G8/F8 -> 0.93621868 | I8: =F8-C8 -> -113 | J8: =G8-D8 -> -94 | K8: =H8-E8 -> 0.021363606
A9: 7 | B9: 苗栗縣 | C9: 1317 | D9: 8 | E9: =D9/C9 -> 0.0060744115 | F9: =COUNTA('清冊(苗栗縣)'!F:F)-1 -> 5 | G9: =COUNTIF('清冊(苗栗縣)'!F:F,"有") -> 5 | H9: =G9/F9 -> 1 | I9: =F9-C9 -> -1312 | J9: =G9-D9 -> -3 | K9: =H9-E9 -> 0.99392559
A10: 8 | B10: 臺中市 | C10: 6582 | D10: 620 | E10: =D10/C10 -> 0.094196293 | F10: =COUNTA('清冊(臺中市)'!F:F)-1 -> 5098 | G10: =COUNTIF('清冊(臺中市)'!F:F,"有") -> 527 | H10: =G10/F10 -> 0.10337387 | I10: =F10-C10 -> -1484 | J10: =G10-D10 -> -93 | K10: =H10-E10 -> 0.0091775792
A11: 9 | B11: 南投縣 | C11: - | D11: - | E11: - | F11: =COUNTA('清冊(南投縣)'!F:F)-1 -> 263 | G11: =COUNTIF('清冊(南投縣)'!F:F,"有") -> 0 | H11: =G11/F11 -> 0 | I11: - | J11: - | K11: - | L11: 未建置交控中心
A12: 10 | B12: 彰化縣 | C12: 2014 | D12: 22 | E12: =D12/C12 -> 0.010923535 | F12: =COUNTA('清冊(彰化縣)'!F:F)-1 -> 11 | G12: =COUNTIF('清冊(彰化縣)'!F:F,"有") -> 11 | H12: =G12/F12 -> 1 | I12: =F12-C12 -> -2003 | J12: =G12-D12 -> -11 | K12: =H12-E12 -> 0.98907646
A13: 11 | B13: 雲林縣 | C13: 1064 | D13: 64 | E13: =D13/C13 -> 0.060150376 | F13: =COUNTA('清冊(雲林縣)'!F:F)-1 -> 49 | G13: =COUNTIF('清冊(雲林縣)'!F:F,"有") -> 49 | H13: =G13/F13 -> 1 | I13: =F13-C13 -> -1015 | J13: =G13-D13 -> -15 | K13: =H13-E13 -> 0.93984962
A14: 12 | B14: 嘉義市 | C14: 698 | D14: 82 | E14: =D14/C14 -> 0.11747851 | F14: =COUNTA('清冊(嘉義市)'!F:F)-1 -> 652 | G14: =COUNTIF('清冊(嘉義市)'!F:F,"有") -> 64 | H14: =G14/F14 -> 0.098159509 | I14: =F14-C14 -> -46 | J14: =G14-D14 -> -18 | K14: =H14-E14 -> -0.019319001
A15: 13 | B15: 嘉義縣 | C15: 1038 | D15: 19 | E15: =D15/C15 -> 0.018304432 | F15: =COUNTA('清冊(嘉義縣)'!F:F)-1 -> 1674 | G15: =-COUNTIF('清冊(嘉義縣)'!F:F,"有") -> 0 | H15: =G15/F15 -> 0 | I15: =F15-C15 -> 636 | J15: =G15-D15 -> -19 | K15: =H15-E15 -> -0.018304432 | L15: 交控中心已拆除
A16: 14 | B16: 臺南市 | C16: 6291 | D16: 4630 | E16: =D16/C16 -> 0.73597202 | F16: =COUNTA('清冊(臺南市)'!F:F)-1 -> 4517 | G16: =COUNTIF('清冊(臺南市)'!F:F,"有") -> 4517 | H16: =G16/F16 -> 1 | I16: =F16-C16 -> -1774 | J16: =G16-D16 -> -113 | K16: =H16-E16 -> 0.26402798
A17: 15 | B17: 高雄市 | C17: 5529 | D17: 1665 | E17: =D17/C17 -> 0.30113945 | F17: =COUNTA('清冊(高雄市)'!F:F)-1 -> 1978 | G17: =COUNTIF('清冊(高雄市)'!F:F,"有") -> 1978 | H17: =G17/F17 -> 1 | I17: =F17-C17 -> -3551 | J17: =G17-D17 -> 313 | K17: =H17-E17 -> 0.69886055
A18: 16 | B18: 屏東縣 | C18: 1500 | D18: 220 | E18: =D18/C18 -> 0.14666667 | F18: =COUNTA('清冊(屏東縣)'!F:F)-1 -> 129 | G18: =COUNTIF('清冊(屏東縣)'!F:F,"有") -> 129 | H18: =G18/F18 -> 1 | I18: =F18-C18 -> -1371 | J18: =G18-D18 -> -91 | K18: =H18-E18 -> 0.85333333
A19: 17 | B19: 宜蘭縣 | C19: 1222 | D19: 184 | E19: =D19/C19 -> 0.15057283 | F19: =COUNTA('清冊(宜蘭縣)'!F:F)-1 -> 43 | G19: =COUNTIF('清冊(宜蘭縣)'!F:F,"有") -> 43 | H19: =G19/F19 -> 1 | I19: =F19-C19 -> -1179 | J19: =G19-D19 -> -141 | K19: =H19-E19 -> 0.84942717
A20: 18 | B20: 花蓮縣 | C20: 759 | D20: 226 | E20: =D20/C20 -> 0.29776021 | F20: =COUNTA('清冊(花蓮縣)'!E:E)-1 -> 128 | G20: =COUNTIF('清冊(花蓮縣)'!F:F,"有") -> 128 | H20: =G20/F20 -> 1 | I20: =F20-C20 -> -631 | J20: =G20-D20 -> -98 | K20: =H20-E20 -> 0.70223979
A21: 19 | B21: 臺東縣 | C21: 371 | D21: 155 | E21: =D21/C21 -> 0.41778976 | F21: =COUNTA('清冊(臺東縣)'!F:F)-1 -> 116 | G21: =COUNTIF('清冊(臺東縣)'!F:F,"有") -> 116 | H21: =G21/F21 -> 1 | I21: =F21-C21 -> -255 | J21: =G21-D21 -> -39 | K21: =H21-E21 -> 0.58221024
A22: 20 | B22: 澎湖縣 | C22: 142 | D22: - | E22: - | F22: =COUNTA('清冊(澎湖縣)'!F:F)-1 -> 146 | G22: =COUNTIF('清冊(澎湖縣)'!F:F,"有") -> 146 | H22: =G22/F22 -> 1 | I22: =F22-C22 -> 4 | J22: - | K22: - | L22: 未建置交控中心，號誌係連線至警察局
A23: 21 | B23: 金門縣 | C23: 50 | D23: 13 | E23: =D23/C23 -> 0.26 | F23: =COUNTA('清冊(金門縣)'!F:F)-1 -> 36 | G23: =COUNTIF('清冊(金門縣)'!F:F,"有") -> 1 | H23: =G23/F23 -> 0.027777778 | I23: =F23-C23 -> -14 | J23: =G23-D23 -> -12 | K23: =H23-E23 -> -0.23222222
A24: 22 | B24: 連江縣 | C24: - | D24: - | E24: - | F24: - | G24: - | H24: - | I24: - | J24: - | K24: - | L24: 未建置交控中心

Sheet 清冊(基隆市)
A1: **填報號誌類型:非特種單閃號誌，三色運作及三色燈箱閃光運作皆請填報
A2: 號誌編號 | B2: 行政區 | C2: 號誌設置位置 | D2: 緯度 | E2: 經度 | F2: 通訊模組
A3: S00001 | B3: 中山區 | C3: 中華路 光華隧道 | D3: 121.7387 | E3: 25.1461 | F3: 有
A4: S000031 | B4: 信義區 | C4: 信二路 義四路 | D4: 121.74834 | E4: 25.13007 | F4: 有
A5: S000032 | B5: 中正區 | C5: 義一路 信七路 | D5: 121.74778 | E5: 25.13622 | F5: 有
A6: S000033 | B6: 仁愛區 | C6: 仁二路 愛四路 | D6: 121.74411 | E6: 25.12911 | F6: 有
A7: S000034 | B7: 仁愛區 | C7: 忠一路 孝四路 港西街 | D7: 121.74009 | E7: 25.13144 | F7: 有
A8: S000035 | B8: 仁愛區 | C8: 仁二路 愛五路 | D8: 121.7455 | E8: 25.12836 | F8: 有
A9: S000036 | B9: 信義區 | C9: 東明路 77巷 | D9: 121.76183 | E9: 25.127719 | F9: 有
A10: S000037 | B10: 信義區 | C10: 東明路 東信路 崇法街 | D10: 121.76437 | E10: 25.128253 | F10: 有
A11: S000038 | B11: 中正區 | C11: 中正路 中正路119巷 | D11: 121.75953 | E11: 25.14142 | F11: 有
A12: S000039 | B12: 中正區 | C12: 正豐街62號 | D12: 121.76148 | E12: 25.14112 | F12: 有
A13: S00004 | B13: 中山區 | C13: 中山一路 西岸聯絡道 | D13: 121.7395 | E13: 25.1338 | F13: 有
A14: S000040 | B14: 中正區 | C14: 祥豐街 正濱國小 | D14: 121.77044 | E14: 25.14672 | F14: 有
... A59: S003801 | B59: 七堵區 | C59: 明德二路15之53號前 | D59: 121.70518 | E59: 25.088085 | F59: 無
A60: S003901 | B60: 七堵區 | C60: 明德二路六堵工業區 | D60: =#N/A -> #N/A | E60: =#N/A -> #N/A | F60: 無
A61: S004001 | B61: 七堵區 | C61: 明德三路長安街 | D61: 121.69247 | E61: 25.077033 | F61: 無
A62: S004101 | B62: 七堵區 | C62: 明德三路長春貨櫃前(移除) | D62: 121.68597 | E62: 25.075595 | F62: 無
A63: S004201 | B63: 七堵區 | C63: 明德一路光明路永富路 | D63: 121.71869 | E63: 25.099813 | F63: 無
A64: S004301 | B64: 七堵區 | C64: 明德一路崇廉街 | D64: 121.71632 | E64: 25.0986 | F64: 無
A65: S004401 | B65: 七堵區 | C65: 明德一路崇孝街 | D65: 121.71092 | E65: 25.096551 | F65: 無
A66: S004501 | B66: 七堵區 | C66: 明德一路崇禮街 | D66: 121.7152 | E66: 25.098111 | F66: 無
A67: S005501 | B67: 暖暖區 | C67: 源遠路193巷 | D67: 121.75151 | E67: 25.098319 | F67: 無
A68: S005601 | B68: 暖暖區 | C68: 源遠路249巷 | D68: 121.7546 | E68: 25.098705 | F68: 無
A69: S005701 | B69: 暖暖區 | C69: 源遠路277巷 | D69: 121.75547 | E69: 25.098885 | F69: 無
A70: S005801 | B70: 暖暖區 | C70: 源遠路325巷 | D70: 121.75763 | E70: 25.099343 | F70: 無
A71: S005901 | B71: 七堵區 | C71: 明德一路光明路 | D71: 121.71028 | E71: 25.092457 | F71: 無
A72: S006201 | B72: 安樂區 | C72: 麥金路八德路 | D72: 121.72851 | E72: 25.114414 | F72: 無
... A170: S018501 | B170: 安樂區 | C170: 基金三路內寮社區 | D170: 121.69443 | E170: 25.15778 | F170: 無

Sheet 清冊(臺北市)
A1: **填報號誌類型:非特種單閃號誌，三色運作及三色燈箱閃光運作皆請填報
A2: 號誌編號 | B2: 號誌設置位置 | C2: 行政區 | D2: 經度 | E2: 緯度 | F2: 通訊模組
A3: S0SSA10 | B3: 老泉街 防汛道路 | C3: 文山區 | D3: 121.55754 | E3: 24.976234 | F3: 有
A4: S0XRU10 | B4: 木新路三段 232巷 | C4: 文山區 | D4: 121.55911 | E4: 24.981323 | F4: 有
A5: S0YPB10 | B5: 木新路三段 寶橋路 | C5: 文山區 | D5: 121.55405 | E5: 24.98002 | F5: 有
A6: S0YRZ10 | B6: 老泉街 恆光橋頭 | C6: 文山區 | D6: 121.56776 | E6: 24.979765 | F6: 有
A7: S1DQU10 | B7: 辛亥路七段 光輝路21巷 | C7: 文山區 | D7: 121.55379 | E7: 24.985535 | F7: 有
A8: S1DSE10 | B8: 興隆路四段 58巷 | C8: 文山區 | D8: 121.56127 | E8: 24.985552 | F8: 有
A9: S1ESA10 | B9: 木新路二段 161巷 | C9: 文山區 | D9: 121.56879 | E9: 24.984015 | F9: 有
A10: S1EUF10 | B10: 指南路二段 政大一街 | C10: 文山區 | D10: 121.57982 | E10: 24.985828 | F10: 有
A11: S1FQB10 | B11: 忠順街一段 26巷 | C11: 文山區 | D11: 121.55913 | E11: 24.984085 | F11: 有
A12: S1FQR10 | B12: 辛亥路七段 20巷 | C12: 文山區 | D12: 121.55314 | E12: 24.986582 | F12: 有
A13: S1GQS10 | B13: 興隆路四段 忠順街二段 | C13: 文山區 | D13: 121.56168 | E13: 24.984468 | F13: 有
A14: S1GQT10 | B14: 西安街一段 文林北路94巷 | C14: 北投區 | D14: 121.51992 | E14: 25.107777 | F14: 有
... A2470: SZZGM10 | B2470: 西安街一段 東陽街 | C2470: 北投區 | D2470: 121.51686 | E2470: 25.111984 | F2470: 有

Sheet 清冊(新北市)
A1: **填報號誌類型:非特種單閃號誌，三色運作及三色燈箱閃光運作皆請填報
A2: 號誌編號 | B2: 行政區 | C2: 號誌設置位置 | D2: 緯度 | E2: 經度 | F2: 通訊模組
A3: 650101 | B3: 三芝區 | C3: 淡金路、錫板里南勢崗(路燈編號441021) | D3: 25.262752 | E3: 121.48052 | F3: 有
A4: S061901 | B4: 中和區 | C4: 景新街、467巷 | D4: 24.9881 | E4: 121.51334 | F4: 有
A5: S127301 | B5: 泰山區 | C5: 文程路、同義街 | D5: 25.049563 | E5: 121.43558 | F5: 有
A6: S135201 | B6: 淡水區 | C6: 中正路1段、63巷 | D6: 25.177776 | E6: 121.4241 | F6: 有
A7: S137001 | B7: 淡水區 | C7: 中山北路3段、新市二路 | D7: 25.19236 | E7: 121.44458 | F7: 有
A8: S173002 | B8: 淡水區 | C8: 後洲路1段、崁頂三路 | D8: 25.201808 | E8: 121.42929 | F8: 有
A9: S174202 | B9: 淡水區 | C9: 新市二路、後洲路 | D9: 25.195918 | E9: 121.42656 | F9: 有
A10: S174302 | B10: 淡水區 | C10: 新市二路、崁頂三路 | D10: 25.194754 | E10: 121.4297 | F10: 有
A11: S174502 | B11: 淡水區 | C11: 新市二路3段、崁頂二路 | D11: 25.193525 | E11: 121.43513 | F11: 有
A12: S192701 | B12: 板橋區 | C12: 僑中一街、大觀路1段28巷 | D12: 25.01108 | E12: 121.44976 | F12: 有
A13: S217201 | B13: 淡水區 | C13: 中山北路2段、新市一路3段 | D13: 25.182976 | E13: 121.44446 | F13: 有
A14: S236401 | B14: 鶯歌區 | C14: 鶯桃路2段、福隆二街(鳳吉四街) | D14: 24.972265 | E14: 121.3258 | F14: 有
A15: S323101 | B15: 淡水區 | C15: 濱海路1段、淡金路2段 | D15: 25.189107 | E15: 121.44685 | F15: 有
... A3794: S650201 | B3794: 淡水區 | C3794: 中正路二段51巷、觀海路 | D3794: 25.181125 | E3794: 121.41764 | F3794: 有

Sheet 清冊(桃園市)
A1: **填報號誌類型:非特種單閃號誌，三色運作及三色燈箱閃光運作皆請填報
A2: 號誌編號 | B2: 行政區 | C2: 號誌設置位置 | D2: 緯度 | E2: 經度 | F2: 通訊模組
A3: S100100 | B3: 桃園區 | C3: 萬壽路二段-山鶯路 | D3: 24.99196 | E3: 121.32259 | F3: 有
A4: S100200 | B4: 桃園區 | C4: 復興路與民生路 | D4: 24.99103 | E4: 121.31493 | F4: 有
A5: S100300 | B5: 桃園區 | C5: 復興路與民族路 | D5: 24.98957 | E5: 121.31017 | F5: 有
A6: S100400 | B6: 桃園區 | C6: 復興路與中正路 | D6: 24.99047 | E6: 121.3131 | F6: 有
A7: S100500 | B7: 桃園區 | C7: 復興路與中山路、縣府路 | D7: 24.9918 | E7: 121.301 | F7: 有
A8: S100600 | B8: 桃園區 | C8: 中山路與正光路 | D8: 24.99092 | E8: 121.295 | F8: 有
A9: S100700 | B9: 桃園區 | C9: 中山路與延壽街 | D9: 24.99109 | E9: 121.29379 | F9: 有
A10: S100800 | B10: 桃園區 | C10: 中山路與國際路 | D10: 24.98979 | E10: 121.28858 | F10: 有
A11: S100900 | B11: 桃園區 | C11: 中山路與上海路 | D11: 24.98766 | E11: 121.28372 | F11: 有
A12: S101000 | B12: 桃園區 | C12: 中山路與明光街 | D12: 24.98409 | E12: 121.27884 | F12: 有
A13: S101100 | B13: 桃園區 | C13: 中山路與高城路 | D13: 24.98106 | E13: 121.27552 | F13: 有
A14: S101200 | B14: 桃園區 | C14: 中山路-龍壽街、永豐路 | D14: 24.97745 | E14: 121.26991 | F14: 有
... A3240: SD01300 | B3240: 復興區 | C3240: 台七線 44.0公里與桃113線往三光村(閃光) | D3240: 24.692696 | E3240: 121.37421 | F3240: 無

Sheet 清冊(新竹縣)
A1: **填報號誌類型:非特種單閃號誌，三色運作及三色燈箱閃光運作皆請填報
A2: 號誌編號 | B2: 行政區 | C2: 號誌設置位置 | D2: 緯度 | E2: 經度 | F2: 通訊模組
A3: 302-001 | B3: 竹北市 | C3: 竹北市台一線中華路66.2K處1483巷口 | D3: 24.85849 | E3: 120.99428 | F3: 無
A4: 302-003 | B4: 竹北市 | C4: 竹北市台一線與鳳岡路口(中華路1150巷) | D4: 24.8549 | E4: 121.00287 | F4: 有
A5: 302-004 | B5: 竹北市 | C5: 竹北市台一線與沿河街口 | D5: 24.85158 | E5: 121.00407 | F5: 有
A6: 302-005 | B6: 竹北市 | C6: 竹北市台一線與東華和籤口 | D6: 24.84986 | E6: 121.00466 | F6: 無
A7: 302-006 | B7: 竹北市 | C7: 竹北市台一線與環北路口 | D7: 24.84905 | E7: 121.00458 | F7: 無
A8: 302-007 | B8: 竹北市 | C8: 竹北市台一線中華路676巷口 | D8: 24.84648 | E8: 121.0056 | F8: 有
A9: 302-008 | B9: 竹北市 | C9: 竹北市台一線與泰和路口 | D9: 24.84376 | E9: 121.00549 | F9: 有
A10: 302-009 | B10: 竹北市 | C10: 竹北市台一線與國盛街與新泰路口 | D10: 24.84193 | E10: 121.00568 | F10: 有
A11: 302-044 | B11: 竹北市 | C11: 竹北市文興路與嘉豐六路口 | D11: 24.81019 | E11: 121.02934 | F11: 有
A12: 302-045 | B12: 竹北市 | C12: 竹北市文興路與嘉豐五路口 | D12: 24.81103 | E12: 121.02774 | F12: 有
A13: 302-046 | B13: 竹北市 | C13: 竹北市文興路與嘉豐二街口 | D13: 24.81195 | E13: 121.02604 | F13: 有
... A395: 303-185 | B395: 湖口鄉 | C395: 湖口鄉中華路與莊敬路口 | D395: 24.865849 | E395: 121.005405 | F395: 無
A396: 303-187 | B396: 湖口鄉 | C396: 湖口鄉新湖路與信德路口 | F396: 無
A397: 303-188 | B397: 湖口鄉 | C397: 湖口鄉榮光路與鳳工三街 | D397: 24.862985 | E397: 121.003406 | F397: 無
A398: 303-189 | B398: 湖口鄉 | C398: 湖口鄉鳳工路與鳳工二街 | D398: 24.862298 | E398: 121.002925 | F398: 無
A399: 303-190 | B399: 湖口鄉 | C399: 湖口鄉鳳工路與鳳工六街 | D399: 24.860944 | E399: 121.002055 | F399: 無
A400: 303-191 | B400: 湖口鄉 | C400: 湖口鄉鳳工路與鳳工八街 | D400: 24.859944 | E400: 121.001306 | F400: 無
A401: 303-192 | B401: 湖口鄉 | C401: 湖口鄉鳳工一街與鳳工六街 | D401: 24.860531 | E401: 121.002897 | F401: 無
A402: 303-193 | B402: 湖口鄉 | C402: 湖口鄉鳳工三街與鳳工六街 | D402: 24.861943 | E402: 121.000345 | F402: 無
A403: 304-001 | B403: 新豐鄉 | C403: 新豐鄉台1線與忠信街口 | D403: 24.87816 | E403: 121.00597 | F403: 有
A404: 304-002 | B404: 新豐鄉 | C404: 新豐鄉台1線南港輪胎前路口 | D404: 24.87804 | E404: 121.00542 | F404: 有
A405: 304-003 | B405: 新豐鄉 | C405: 新豐鄉台1線與唐榮科技園區前路口 | D405: 24.87573 | E405: 121.00345 | F405: 有
A406: 304-004 | B406: 新豐鄉 | C406: 新豐鄉台1線與中興路口 | D406: 24.87307 | E406: 121.00053 | F406: 有
A407: 304-005 | B407: 新豐鄉 | C407: 新豐鄉台1線與文昌街口 | D407: 24.87247 | E407: 120.99937 | F407: 有
A408: 304-007 | B408: 新豐鄉 | C408: 新豐鄉台1線與工業區地下道路口 | D408: 24.87117 | E408: 120.99811 | F408: 有
... A695: 310-097 | B695: 竹東鎮 | C695: 竹東鎮公道五路1k+560處 | D695: 24.78584 | E695: 121.0343 | F695: 有
A696: 310-098 | B696: 竹東鎮 | C696: 竹東鎮公道五路1k+620處 | F696: 無
A697: 310-099 | B697: 竹東鎮 | C697: 竹東鎮公道五路與員山路 | D697: 24.78359 | E697: 121.03832 | F697: 無
A698: 310-100 | B698: 竹東鎮 | C698: 竹東鎮公道五路2k+251處 | D698: 24.781680 | E698: 121.043061 | F698: 無
A699: 310-101 | B699: 竹東鎮 | C699: 竹東鎮公道五路3k+193處 | D699: 24.781829 | E699: 121.049700 | F699: 無
A700: 310-102 | B700: 竹東鎮 | C700: 竹東鎮公道五路3k+800處 | D700: 24.77846 | E700: 121.05533 | F700: 無
A701: 310-103 | B701: 竹東鎮 | C701: 竹東鎮公道五路3k+900處與光明路 | D701: 24.778411 | E701: 121.055351 | F701: 無
A702: 310-104 | B702: 竹東鎮 | C702: 竹東鎮光明路與公道五路引道路口 | D702: 24.779036 | E702: 121.055367 | F702: 無
A703: 310-105 | B703: 竹東鎮 | C703: 竹東鎮中興路一段108巷 | D703: 24.75344 | E703: 121.07445 | F703: 無
A704: 310-106 | B704: 竹東鎮 | C704: 竹東鎮中興路一段金福街 | D704: 24.75466 | E704: 121.07185 | F704: 無
A705: 310-107 | B705: 竹東鎮 | C705: 竹東鎮中興路一段229巷/214巷 | D705: 24.75603 | E705: 121.0703 | F705: 無
A706: 310-108 | B706: 竹東鎮 | C706: 竹東鎮中興路二段101巷/122巷 | D706: 24.75932 | E706: 121.06475 | F706: 無
A707: 310-109 | B707: 竹東鎮 | C707: 竹東鎮中興路二段169巷/172巷 | D707: 24.75973 | E707: 121.06375 | F707: 無
...

Sheet 清冊(新竹市)
A1: **填報號誌類型:非特種單閃號誌，三色運作及三色燈箱閃光運作皆請填報
A2: 號誌編號 | B2: 行政區 | C2: 號誌設置位置 | D2: 緯度 | E2: 經度 | F2: 通訊模組
A3: TC001 | B3: 北區 | C3: 經國路二段與水田街路口 | D3: 24.812852 | E3: 120.96585 | F3: 有
A4: TC002 | B4: 東區 | C4: 經國路一段與民權路及國華街路口 | D4: 24.81412 | E4: 120.97082 | F4: 有
A5: TC003 | B5: 東區 | C5: 經國路一段與民生路及光華東街口 | D5: 24.814337 | E5: 120.97422 | F5: 有
A6: TC004 | B6: 東區 | C6: 經國路一段與民主路及田美三街口 | D6: 24.814547 | E6: 120.97692 | F6: 有
A7: TC005 | B7: 東區 | C7: 經國路一段與自由路口 | D7: 24.814545 | E7: 120.97968 | F7: 有
A8: TC006 | B8: 香山區 | C8: 中華路四段與經國三段(南端)路口 | D8: 24.796597 | E8: 120.95239 | F8: 有
A9: TC007 | B9: 北區 | C9: 中華路三段與中山路口 | D9: 24.796636 | E9: 120.9552 | F9: 有
A10: TC008 | B10: 北區 | C10: 中華路三段與林森路及振興路口 | D10: 24.796729 | E10: 120.96069 | F10: 有
A11: TC009 | B11: 東區 | C11: 中華路二段與南外街路口 | D11: 24.798691 | E11: 120.96624 | F11: 有
A12: TC010 | B12: 東區 | C12: 中華路二段與中正路及林森路口 | D12: 24.801695 | E12: 120.97113 | F12: 有
A13: TC011 | B13: 東區 | C13: 中華路二段與東大路及東門街路口 | D13: 24.804181 | E13: 120.97489 | F13: 有
A14: TC034 | B14: 北區 | C14: 經國路二段與延平路一段路口 | D14: 24.804771 | E14: 120.9556 | F14: 有
A15: TC035 | B15: 北區 | C15: 經國路二段與和平路口 | D15: 24.80639 | E15: 120.956 | F15: 有
A16: TC036 | B16: 北區 | C16: 經國路二段與西大路口 | D16: 24.809033 | E16: 120.96015 | F16: 有
A17: TC037 | B17: 北區 | C17: 經國路二段與城北街路口 | D17: 24.811319 | E17: 120.96355 | F17: 有
A18: TC038 | B18: 北區 | C18: 經國路二段與中正路口 | D18: 24.811965 | E18: 120.96443 | F18: 有
A19: TC039 | B19: 北區 | C19: 經國路二段與東大路二段路口 | D19: 24.813858 | E19: 120.96739 | F19: 有
A20: TC040 | B20: 東區 | C20: 經國路一段與光華街路口 | D20: 24.814225 | E20: 120.97248 | F20: 有
... A316: TC420 | B316: 東區 | C316: 公竹路與後轉運站入口 | D316: 24.801624 | E316: 120.97459 | F316: 有
A317: TC421 | C317: 東南一街與後轉運站出口 | F317: 有
A318: TC422 | B318: 東區 | C318: 東光路與八德路口 | D318: 24.802715 | E318: 120.98693 | F318: 有
A319: TC423 | B319: 北區 | C319: 東大路三段與公道五路五段 | D319: 24.832419 | E319: 120.95353 | F319: 有
A320: TC439 | B320: 東區 | C320: 慈濟路與埔頂二路 | D320: 24.790631 | E320: 121.01409 | F320: 有
A321: TC440 | B321: 北區 | C321: 東大路三段與東大路三段291巷 | D321: 24.835057 | E321: 120.94559 | F321: 有
A322: TC441 | B322: 北區 | C322: 東大路三段與東大路三段377巷 | D322: 24.836687 | E322: 120.94336 | F322: 有
A323: TC442 | B323: 東區 | C323: 光復路一段544巷與光復路一段544巷60弄 | D323: 24.788149 | E323: 121.01134 | F323: 有
A324: TC443 | B324: 北區 | C324: 中正路與485巷口 | D324: 24.816175 | E324: 120.95835 | F324: 有
A325: TC444 | B325: 東區 | C325: 高峰路與研新四路 | D325: 24.776047 | E325: 120.98466 | F325: 有
A326: TC445 | B326: 香山區 | C326: 牛埔東路與香山國小前 | D326: 24.796152 | E326: 120.9439 | F326: 有
A327: TC446 | B327: 北區 | C327: 延平路二段與291巷口 | D327: 24.805028 | E327: 120.95174 | F327: 有
A328: TC447 | B328: 東區 | C328: 柴橋路康橋國小 | D328: 24.769239 | E328: 120.96559 | F328: 有
A329: TC448 | B329: 北區 | C329: 湳雅街與湳雅街151巷口 | D329: 24.819653 | E329: 120.97282 | F329: 有
... A396: TC530 | B396: 北區 | C396: 中正路 & 城北街 | D396: 24.813831 | E396: 120.96303 | F396: 有
A397: TC531 | B397: 東區 | C397: 高峰路 & 95巷 | D397: 24.792187, | E397: 120.97369 | F397: 有
A398: TC532 | B398: 北區 | C398: 延平路三段 & 515巷 | D398: 24.838472 | E398: 120.93273 | F398: 有
A399: TC533 | B399: 東區 | C399: 公道五路一段 & 慈濟路(北端) | D399: 24.813831 | E399: 120.96303 | F399: 有
A400: TC534 | B400: 東區 | C400: 高峰路 & 明湖路243巷 | D400: 24.788586 | E400: 120.97498 | F400: 有
A401: TC535 | B401: 北區 | C401: 西大路 & 竹文街 | D401: 24.811842 | E401: 120.95558 | F401: 有
...

Sheet 清冊(苗栗縣)
A1: **填報號誌類型:非特種單閃號誌，三色運作及三色燈箱閃光運作皆請填報
A2: 號誌編號 | B2: 行政區 | C2: 號誌設置位置 | D2: 緯度 | E2: 經度 | F2: 通訊模組
A3: MIA-TC401 | B3: 頭份市 | C3: 建國路/中華路 | D3: 24.692989 | E3: 120.91481 | F3: 有
A4: MIA-TC402 | B4: 頭份市 | C4: 建國路/忠孝二路 | D4: 24.69494 | E4: 120.91135 | F4: 有
A5: MIA-TC403 | B5: 頭份市 | C5: 建國路/中興路 | D5: 24.696066 | E5: 120.90931 | F5: 有
A6: MIA-TC404 | B6: 頭份市 | C6: 自強路/中華路 | D6: 24.69039 | E6: 120.9128 | F6: 有
A7: MIA-TCTCROSS | B7: 苗栗市 | C7: 英才路/自治路 | D7: 24.565441 | E7: 120.82086 | F7: 有

Sheet 清冊(臺中市)
A1: 號誌編號 | B1: 行政區 | C1: 號誌設置位置 | D1: 緯度 | E1: 經度 | F1: 通訊模組
A2: 0001 | B2: 南區 | C2: 復興路三段&復興路四段&台中路 | D2: 24.134557 | E2: 120.68277 | F2: 無
A3: 0002 | B3: 西區 | C3: 建國路&民權路&台中路 | D3: 24.135919 | E3: 120.68207 | F3: 有
A4: 0003 | B4: 中區 | C4: 臺灣大道一段&三民路二段 | D4: 24.142483 | E4: 120.67936 | F4: 有
A5: 0004 | B5: 中區 | C5: 中華路一段&臺灣大道一段 | D5: 24.144991 | E5: 120.67641 | F5: 有
A6: 0005 | B6: 西區 | C6: 臺灣大道二段&五權路 | D6: 24.147634 | E6: 120.6733 | F6: 有
A7: 0006 | B7: 中區 | C7: 自由路二段&臺灣大道一段 | D7: 24.140076 | E7: 120.68203 | F7: 有
A8: 0007 | B8: 西區 | C8: 民權路&三民路二段 | D8: 24.140165 | E8: 120.67705 | F8: 有
A9: 0008 | B9: 西區 | C9: 自由路二段&民權路 | D9: 24.137945 | E9: 120.67975 | F9: 有
A10: 0009 | B10: 北區 | C10: 中清路一段&五權路&公園路 | D10: 24.151127 | E10: 120.67742 | F10: 有
A11: 0010 | B11: 西區 | C11: 三民路一段&林森路 | D11: 24.135833 | E11: 120.67296 | F11: 有
A12: 0011 | B12: 北區 | C12: 公園路&三民路二段&三民路三段&精武路 | D12: 24.144747 | E12: 120.68208 | F12: 有
A13: 0012 | B13: 南區 | C13: 復興路三段&國光路 | D13: 24.131674 | E13: 120.67682 | F13: 無
... A3755: 后里098 | B3755: 后里區 | C3755: 尾社路&重劃西路 | D3755: 24.338303 | E3755: 120.72476 | F3755: 無
A3756: 后里099 | B3756: 后里區 | C3756: 大圳路&文化路 | D3756: 24.308991036456046, | E3756: 120.7101 | F3756: 無
A3757: 后里100 | B3757: 后里區 | C3757: 三線路&甲后路三段145巷&四月路 | D3757: 24.313039 | E3757: 120.6775 | F3757: 無
A3758: 沙鹿001 | B3758: 沙鹿區 | C3758: 鎮南路二段&平等路&鎮南路二段93巷 | D3758: 24.219725 | E3758: 120.5699 | F3758: 無
A3759: 沙鹿002 | B3759: 沙鹿區 | C3759: 鎮南路二段&南斗路 | D3759: 24.217318 | E3759: 120.57061 | F3759: 無
A3760: 沙鹿003 | B3760: 沙鹿區 | C3760: 自由路&鎮南路二段 | D3760: 24.220547 | E3760: 120.56954 | F3760: 無
A3761: 沙鹿004 | B3761: 沙鹿區 | C3761: 鎮南路二段&沙田路 | D3761: 24.234729 | E3761: 120.55872 | F3761: 無
A3762: 沙鹿005 | B3762: 沙鹿區 | C3762: 鎮南路一段&屏西路 | D3762: 24.215742 | E3762: 120.57106 | F3762: 無
A3763: 沙鹿006 | B3763: 沙鹿區 | C3763: 中山路&七賢路 | D3763: 24.236931 | E3763: 120.56813 | F3763: 無
A3764: 沙鹿007 | B3764: 沙鹿區 | C3764: 鎮南路二段&光華路 | D3764: 24.233633 | E3764: 120.56252 | F3764: 無
A3765: 沙鹿008 | B3765: 沙鹿區 | C3765: 光華路&三民路&七賢路 | D3765: 24.242422 | E3765: 120.57133 | F3765: 無
A3766: 沙鹿009 | B3766: 沙鹿區 | C3766: 三民路&七賢路&七賢南路&福田南街 | D3766: 24.241376 | E3766: 120.57089 | F3766: 無
A3767: 沙鹿010 | B3767: 沙鹿區 | C3767: 中山路&鎮政路 | D3767: 24.236907 | E3767: 120.56666 | F3767: 無
A3768: 沙鹿011 | B3768: 沙鹿區 | C3768: 中山路&長春北路&長春路&中山路中鋒南巷 | D3768: 24.254161 | E3768: 120.56796 | F3768: 無
... A4577: 潭子006 | B4577: 潭子區 | C4577: 豐興路一段&臺中地方法院簡易庭 | D4577: 24.193324 | E4577: 120.71971 | F4577: 無
A4578: 潭子007 | B4578: 潭子區 | C4578: 豐興路一段&慈濟醫院 | D4578: 24.193792915015063, | E4578: 120.71987 | F4578: 無
A4579: 潭子008 | B4579: 潭子區 | C4579: 豐興路一段&慈濟醫院入口 | D4579: 24.195698 | E4579: 120.72113 | F4579: 無
A4580: 潭子009 | B4580: 潭子區 | C4580: 豐興路一段&慈濟醫院出口 | D4580: 24.196233 | E4580: 120.72145 | F4580: 無
A4581: 潭子010 | B4581: 潭子區 | C4581: 豐興路一段＆豐興路一段192巷 | D4581: 24.19795 | E4581: 120.72188 | F4581: 無
A4582: 潭子011 | B4582: 潭子區 | C4582: 豐興路一段&豐興路一段437巷&豐興路一段400巷 | D4582: 24.200601 | E4582: 120.72237 | F4582: 無
A4583: 潭子012 | B4583: 潭子區 | C4583: 豐興路二段&豐興路二段338巷 | D4583: 24.213126 | E4583: 120.72271 | F4583: 無
A4584: 潭子013 | B4584: 潭子區 | C4584: 潭子街三段&福潭路 | D4584: 24.215414 | E4584: 120.70588 | F4584: 無
A4585: 潭子014 | B4585: 潭子區 | C4585: 昌平路三段&昌平路三段178巷&昌平路三段201巷 | D4585: 24.204558 | E4585: 120.67399 | F4585: 無
A4586: 潭子015 | B4586: 潭子區 | C4586: 昌平路三段&民族路一段 | D4586: 24.203882 | E4586: 120.67428 | F4586: 無
A4587: 潭子016 | B4587: 潭子區 | C4587: 昌平路三段&昌平路三段101巷&大明一路 | D4587: 24.203219 | E4587: 120.67467 | F4587: 無
A4588: 潭子017 | B4588: 潭子區 | C4588: 豐興路一段&環中東路一段 | D4588: 24.195295 | E4588: 120.72057 | F4588: 無
A4589: 潭子018 | B4589: 潭子區 | C4589: 環中東路一段&潭興路一段165巷 | D4589: 24.197679 | E4589: 120.71827 | F4589: 無
...

Sheet 清冊(南投縣)
A1: **填報號誌類型:非特種單閃號誌，三色運作及三色燈箱閃光運作皆請填報
A2: 號誌編號 | B2: 行政區 | C2: 號誌設置位置 | D2: 緯度 | E2: 經度 | F2: 通訊模組
A3: ZG002 | B3: 中寮鄉 | C3: 139縣道47K+450與南投休息站 | D3: 23.896472 | E3: 120.71275 | F3: 無
A4: ZG004 | B4: 中寮鄉 | C4: 中山橋 | D4: 23.89244 | E4: 120.72192 | F4: 無
A5: ZG005 | B5: 中寮鄉 | C5: 永平路與竹坑巷口 | D5: 23.89394 | E5: 120.73086 | F5: 無
A6: ZG009 | B6: 中寮鄉 | C6: 永平路與永安街口 | D6: 23.878545 | E6: 120.76871 | F6: 無
A7: ZG015 | B7: 中寮鄉 | C7: 139縣道(永平路)與投26鄉道(永樂路)路口 | D7: 23.878426 | E7: 120.770189 | F7: 無
A8: ZG016 | B8: 中寮鄉 | C8: 龍南路191-9號前 | D8: 23.934618 | E8: 120.75963 | F8: 無
A9: RA004 | B9: 仁愛鄉 | C9: 台14縣(信義巷) | D9: 24.03208 | E9: 121.14233 | F9: 無
A10: SL004 | B10: 水里鄉 | C10: 民族路與民族橋 | D10: 23.814871 | E10: 120.85426 | F10: 無
A11: SL005 | B11: 水里鄉 | C11: 民族路與民族橋 | D11: 23.815458 | E11: 120.85388 | F11: 無
A12: SL011 | B12: 水里鄉 | C12: 中正路與民生路 | D12: 23.815958 | E12: 120.85454 | F12: 無
A13: MG004 | B13: 名間鄉 | C13: 南田路往養德禪寺(投30鄉道) | D13: 23.87389 | E13: 120.65299 | F13: 無
A14: MG008 | B14: 名間鄉 | C14: 150縣道與139乙縣道 | D14: 23.86085 | E14: 120.63277 | F14: 無
A15: MG026 | B15: 名間鄉 | C15: 名松路一段、投41鄉道 | D15: 23.8397 | E15: 120.68015 | F15: 無
A16: MG028 | B16: 名間鄉 | C16: 名松路與名山路口 | D16: 23.84242 | E16: 120.68554 | F16: 無
A17: MG029 | B17: 名間鄉 | C17: 名松路一段2號前 | D17: 23.84237 | E17: 120.69676 | F17: 無
A18: MG036 | B18: 名間鄉 | C18: 新大巷與蓮蕉巷口 | D18: 23.87812 | E18: 120.67969 | F18: 無
A19: MG037 | B19: 名間鄉 | C19: 彰南路與名中街 | D19: 23.846 | E19: 120.69559 | F19: 無
A20: MG040 | B20: 名間鄉 | C20: 董門巷與庄仔巷口 | D20: 23.83706 | E20: 120.69591 | F20: 無
A21: ZS010 | B21: 竹山鎮 | C21: 大智路與加正巷口 | D21: 23.751187 | E21: 120.68439 | F21: 無
... A265: CT100 | B265: 草屯鎮 | C265: 永安路往武安宮 | D265: 23.980973 | E265: 120.72443 | F265: 無

Sheet 清冊(彰化縣)
A1: **填報號誌類型:非特種單閃號誌，三色運作及三色燈箱閃光運作皆請填報
A2: 號誌編號 | B2: 行政區 | C2: 號誌設置位置 | D2: 緯度 | E2: 經度 | F2: 通訊模組
A3: CWH-TC001 | B3: 和美鎮 | C3: 彰美路六段/道周路 | D3: 24.11736 | E3: 120.49413 | F3: 有
A4: CWH-TC002 | B4: 和美鎮 | C4: 彰美路六段/61巷/義勇街 | D4: 24.11339 | E4: 120.49752 | F4: 有
A5: CWH-TC003 | B5: 和美鎮 | C5: 彰美路五段/美寮路二段/中山路 | D5: 24.11235 | E5: 120.49837 | F5: 有
A6: CWH-TC004 | B6: 和美鎮 | C6: 彰美路五段/愛德路/德美路 | D6: 24.10927 | E6: 120.50086 | F6: 有
A7: CWH-TC016 | B7: 和美鎮 | C7: 彰美路二段/446巷/451巷 | D7: 24.09835 | E7: 120.52561 | F7: 有
A8: CWH-TC017 | B8: 和美鎮 | C8: 彰美路二段/東發路 | D8: 24.09612 | E8: 120.52849 | F8: 有
A9: CWH-TC018 | B9: 和美鎮 | C9: 彰美路二段三五橡膠廠//東安路 | D9: 24.09306 | E9: 120.53212 | F9: 有
A10: CWH-TC019 | B10: 和美鎮 | C10: 彰美路二段/彰新路一段32巷 | D10: 24.09232 | E10: 120.53341 | F10: 有
A11: CWH-TC020 | B11: 彰化市 | C11: 彰美路一段/彰和路一段 | D11: 24.08998 | E11: 120.53635 | F11: 有
A12: CWH-TC021 | B12: 彰化市 | C12: 卦山路/溫泉街(城市車旅停車場出入口) | D12: 24.07707 | E12: 120.54906 | F12: 有
A13: CWH-TC022 | B13: 彰化市 | C13: 中山路(彰化縣政府側門) | D13: 24.07507 | E13: 120.54488 | F13: 有

Sheet 清冊(雲林縣)
A1: **填報號誌類型:非特種單閃號誌，三色運作及三色燈箱閃光運作皆請填報
A2: 號誌編號 | B2: 行政區 | C2: 號誌設置位置 | D2: 緯度 | E2: 經度 | F2: 通訊模組
A3: YUN-S000001 | B3: 斗六市 | C3: 台3線/大學路 | D3: 23.69676 | E3: 120.53801 | F3: 有
A4: YUN-S000002 | B4: 斗六市 | C4: 台3線/中山路533巷 | D4: 23.69543 | E4: 120.53812 | F4: 有
A5: YUN-S000003 | B5: 斗六市 | C5: 台3線/龍潭路 | D5: 23.69415 | E5: 120.53815 | F5: 有
A6: YUN-S000004 | B6: 斗六市 | C6: 台3線/仁義路3巷 | D6: 23.69135 | E6: 120.53832 | F6: 有
A7: YUN-S000005 | B7: 斗六市 | C7: 台3線/雲科大側門 | D7: 23.69062 | E7: 120.53838 | F7: 有
A8: YUN-S000014 | B8: 斗六市 | C8: 仁義路與外環道南端 | D8: 23.6755 | E8: 120.53772 | F8: 有
A9: YUN-S000015 | B9: 斗六市 | C9: 台3線/光明路 | D9: 23.67477 | E9: 120.53748 | F9: 有
A10: YUN-S000016 | B10: 斗六市 | C10: 台3線/三樂路 | D10: 23.67378 | E10: 120.53729 | F10: 有
A11: YUN-S000017 | B11: 斗六市 | C11: 台3線/泰安路 | D11: 23.67312 | E11: 120.53705 | F11: 有
A12: YUN-S000018 | B12: 斗六市 | C12: 古坑交流道北匝道 | D12: 23.67002 | E12: 120.53691 | F12: 有
A13: YUN-S000019 | B13: 斗六市 | C13: 古坑交流道南匝道 | D13: 23.66801 | E13: 120.53754 | F13: 有
A14: YUN-S000020 | B14: 斗六市 | C14: 台3線/頂柴路 | D14: 23.6635 | E14: 120.53926 | F14: 有
... A51: YUN-S000074 | B51: 北港鎮 | C51: 大同路與建國國中前 | D51: 23.57371 | E51: 120.29553 | F51: 有

Sheet 清冊(嘉義縣)
A1: **填報號誌類型:非特種單閃號誌，三色運作及三色燈箱閃光運作皆請填報
A2: 號誌編號 | B2: 行政區 | C2: 號誌設置位置 | D2: 緯度 | E2: 經度 | F2: 通訊模組
A3: IA-001 | B3: 太保 | C3: 159線與麻太路 | F3: 無
A4: IA-002 | B4: 太保 | C4: 168線往梅厝里(太保市168線21K) | F4: 無
A5: IA-003 | B5: 太保 | C5: 嘉64線5K管事厝23號 | F5: 無
A6: IA-004 | B6: 太保 | C6: 中正路與中興路 | F6: 無
A7: IA-005 | B7: 太保 | C7: 台37線與嘉43線(後庄里) | F7: 無
A8: IA-006 | B8: 太保 | C8: 嘉45線與台82線(西向出口) | F8: 無
A9: IA-007 | B9: 太保 | C9: 168線與太保二路 | F9: 無
A10: IA-008 | B10: 太保 | C10: 168線與太保國中 | F10: 無
A11: IA-009 | B11: 太保 | C11: 168線與太保國小 | F11: 無
A12: IA-010 | B12: 太保 | C12: 嘉49線與台電太保服務所 | F12: 無
A13: IA-011 | B13: 太保 | C13: 嘉45線(新)與嘉45線(舊) | F13: 無
A14: IA-012 | B14: 太保 | C14: 嘉49線與嘉43線 | F14: 無
... A60: IA-058 | B60: 太保 | C60: 高鐵西路南側停車場 | F60: 無
A61: IA-059 | B61: 太保 | F61: 無
A62: IA-060 | B62: 太保 | C62: 168線與安東國小 | F62: 無
A63: IA-061 | B63: 太保 | C63: 故宮大道與太子大道 | F63: 無
A64: IA-062 | B64: 太保 | C64: 168線與嘉43-1線(崙仔頂) | F64: 無
A65: IA-063 | B65: 太保 | C65: 168線與嘉43-1線(東勢寮) | F65: 無
A66: IA-064 | B66: 太保 | C66: 167線與嘉39線 | F66: 無
A67: IA-065 | B67: 太保 | C67: 168線與嘉49線 | F67: 無
A68: IA-066 | B68: 太保 | C68: 中山路與中興路 | F68: 無
A69: IA-067 | B69: 太保 | C69: 博學路與信義二路 | F69: 無
A70: IA-068 | B70: 太保 | C70: 三合路大圳旁 | F70: 無
A71: IA-069 | B71: 太保 | C71: 159線與三合路 | F71: 無
A72: IA-070 | B72: 太保 | C72: 三合路與北港路二段403巷 | F72: 無
A73: IA-071 | B73: 太保 | C73: 159線與中華賓士 | F73: 無
... A98: IA-095 | B98: 太保 | C98: 159線與南新派出所 | F98: 無
B99: 太保 | C99: 159線與南新派出所 | F99: 無
A100: IA-096 | B100: 太保 | C100: 嘉64線與南埤路120巷 | F100: 無
A101: IA-097 | B101: 太保 | C101: 太保埤南路南新老人會 | F101: 無
A102: IA-098 | B102: 太保 | C102: 159線北港路二段105巷 | F102: 無
A103: IA-099 | B103: 太保 | C103: 159線南亞塑膠門口 | F103: 無
A104: IA-100 | B104: 太保 | C104: 麻太路上上牙醫 | F104: 無
A105: IA-101 | B105: 太保 | C105: 159線與中正路二段137巷 | F105: 無
A106: IA-102 | B106: 太保 | C106: 159線與北港路二段424巷 | F106: 無
A107: IA-103 | B107: 太保 | C107: 159線與北港路二段661巷 | F107: 無
A108: IA-104 | B108: 太保 | C108: 159線與友良實業 | F108: 無
A109: IA-105 | B109: 太保 | C109: 159線與嘉太變電所 | F109: 無
...

Sheet 清冊(嘉義市)
A1: **填報號誌類型:非特種單閃號誌，三色運作及三色燈箱閃光運作皆請填報
A2: 號誌編號 | B2: 行政區 | C2: 號誌設置位置 | D2: 緯度 | E2: 經度 | F2: 通訊模組
A3: CYI-S200101 | B3: 西區 | C3: 北港路-無名路 | D3: 23.492722 | E3: 120.39598 | F3: 有
A4: CYI-S200201 | B4: 西區 | C4: 北港路-埤竹路-竹子腳巷 | D4: 23.491966 | E4: 120.39784 | F4: 有
A5: CYI-S200301 | B5: 西區 | C5: 北港路-保福一路 | D5: 23.489948 | E5: 120.40455 | F5: 有
A6: CYI-S200401 | B6: 西區 | C6: 北港路-保福路 | D6: 23.48935 | E6: 120.40653 | F6: 有
A7: CYI-S202201 | B7: 西區 | C7: 民族路-西榮街 | D7: 23.475617 | E7: 120.44549 | F7: 無
A8: CYI-S202301 | B8: 西區 | C8: 民族路-民生北路 | D8: 23.475719 | E8: 120.4466 | F8: 無
A9: CYI-S202401 | B9: 西區 | C9: 民族路-忠義街 | D9: 23.475846 | E9: 120.44772 | F9: 無
A10: CYI-S202501 | B10: 西區 | C10: 民族路-國華街 | D10: 23.475919 | E10: 120.44885 | F10: 無
A11: CYI-S202601 | B11: 西區 | C11: 民族路-文化路 | D11: 23.476024 | E11: 120.45001 | F11: 有
A12: CYI-S202701 | B12: 西區 | C12: 中山路-永和街 | D12: 23.476225 | E12: 120.43987 | F12: 有
A13: CYI-S202801 | B13: 西區 | C13: 中山路-蘭井街 | D13: 23.476749 | E13: 120.44012 | F13: 有
A14: CYI-S202901 | B14: 西區 | C14: 中山路-光彩街 | D14: 23.47754 | E14: 120.4406 | F14: 有
... A317: CYI-S325501 | B317: 西區 | C317: 興美六路-南京東街 | D317: 23.45859 | E317: 120.44597 | F317: 無
A318: CYI-S325601 | B318: 西區 | C318: 南京東街-民生南路485巷 | D318: =#N/A -> #N/A | E318: =#N/A -> #N/A | F318: 無
A319: CYI-S325701 | B319: 西區 | C319: 湖美二路-健康十七街 | D319: 23.457861 | E319: 120.44572 | F319: 無
A320: CYI-S325801 | B320: 西區 | C320: 湖美二路-健康十三路 | D320: 23.45243 | E320: 120.44548 | F320: 無
A321: CYI-S325901 | B321: 西區 | C321: 湖美二路-健康十二路 | D321: 23.451672 | E321: 120.44547 | F321: 無
A322: CYI-S326001 | B322: 西區 | C322: 湖美二路-健康十街 | D322: 23.451091 | E322: 120.44547 | F322: 無
A323: CYI-S326101 | B323: 西區 | C323: 湖美二路-健康八街 | D323: 23.44972 | E323: 120.44545 | F323: 無
A324: CYI-S326201 | B324: 西區 | C324: 湖美二路-健康七街 | D324: 23.449098 | E324: 120.44545 | F324: 無
A325: CYI-S326301 | B325: 西區 | C325: 湖美二路-健康五街 | D325: 23.448491 | E325: 120.44545 | F325: 無
A326: CYI-S326401 | B326: 西區 | C326: 湖美二路-健康三路 | D326: 23.447847 | E326: 120.44544 | F326: 無
A327: CYI-S326501 | B327: 西區 | C327: 湖美二路-健康二路 | D327: 23.446804 | E327: 120.44543 | F327: 無
A328: CYI-S326601 | B328: 西區 | C328: 湖美三路-健康十三路-健康十五街 | D328: 23.452454 | E328: 120.4441 | F328: 無
A329: CYI-S326701 | B329: 西區 | C329: 湖美三路-健康十二路 | D329: 23.45169 | E329: 120.4441 | F329: 無
A330: CYI-S326801 | B330: 西區 | C330: 湖美三路-健康十街 | D330: 23.451118 | E330: 120.44409 | F330: 無
... A654: CYI-S621201 | B654: 東區 | C654: 軍輝路-興仁街 | D654: 23.455855 | E654: 120.46358 | F654: 無

Sheet 清冊(臺南市)
A1: **填報號誌類型:非特種單閃號誌，三色運作及三色燈箱閃光運作皆請填報
A2: 號誌編號 | B2: 行政區 | C2: 號誌設置位置 | D2: 緯度 | E2: 經度 | F2: 通訊模組
A3: S000101 | B3: 安平區 | C3: 平通路與健康二街口 | D3: 120.17415 | E3: 22.993232 | F3: 有
A4: S000201 | B4: 仁德區 | C4: 二仁路二段與奇美博物館前 | D4: 120.22098 | E4: 22.934563 | F4: 有
A5: S000301 | B5: 南區 | C5: 明興路與興南街口 | D5: 120.18539 | E5: 22.925135 | F5: 有
A6: S000401 | B6: 北區 | C6: 西門路四段與小北路口 | D6: 120.20605 | E6: 23.006164 | F6: 有
A7: S000501 | B7: 北區 | C7: 長榮路五段與北門路二段口 | D7: 120.21697 | E7: 23.012774 | F7: 有
A8: S000601 | B8: 南區 | C8: 永華路一段與大智街口 | D8: 120.19268 | E8: 22.988004 | F8: 有
A9: S000701 | B9: 北區 | C9: 北門路一段與東豐路口 | D9: 120.21361 | E9: 23.004 | F9: 有
A10: S000801 | B10: 南區 | C10: 林森路一段與大同路一段口 | D10: 120.21215 | E10: 22.981045 | F10: 有
A11: S000901 | B11: 中西區 | C11: 金華路三段與民生路二段口 | D11: 120.19391 | E11: 22.996122 | F11: 有
A12: S001001 | B12: 南區 | C12: 金華路二段與永華路一段口 | D12: 120.19204 | E12: 22.988118 | F12: 有
A13: S005001 | B13: 南區 | C13: 大同路二段與國民路口 | D13: 120.21596 | E13: 22.967411 | F13: 有
A14: S005101 | B14: 中西區 | C14: 南門路與友愛街口 | D14: 120.20481 | E14: 22.990808 | F14: 有
... A4519: S503201 | B4519: 玉井區 | C4519: 台84線與瑞豐汽車修護廠前 | D4519: 120.44835 | E4519: 23.126228 | F4519: 有

Sheet 清冊(高雄市)
A1: **填報號誌類型:非特種單閃號誌，三色運作及三色燈箱閃光運作皆請填報
A2: 號誌編號 | B2: 行政區 | C2: 號誌設置位置 | D2: 緯度 | E2: 經度 | F2: 通訊模組
A3: S000101 | B3: 左營區 | C3: 民族一路、華夏路 | D3: 22.68791 | E3: 120.32085 | F3: 有
A4: S000201 | B4: 左營區 | C4: 民族一路、重愛路 | D4: 22.68297 | E4: 120.31987 | F4: 有
A5: S000301 | B5: 左營區 | C5: 民族一路、榮佑路 | D5: 22.68207 | E5: 120.3197 | F5: 有
A6: S000401 | B6: 左營區 | C6: 民族一路901巷 | D6: 22.68109 | E6: 120.31947 | F6: 有
A7: S000501 | B7: 左營區 | C7: 民族一路、榮耀街 | D7: 22.68036 | E7: 120.31934 | F7: 有
A8: S000601 | B8: 左營區 | C8: 民族一路、大中一路 | D8: 22.67888 | E8: 120.31905 | F8: 有
A9: S000801 | B9: 左營區 | C9: 民族一路、菜公一路 | D9: 22.67543 | E9: 120.31842 | F9: 有
A10: S000901 | B10: 左營區 | C10: 民族一路、文藻外語學院 | D10: 22.67095 | E10: 120.31753 | F10: 有
A11: S001001 | B11: 三民區 | C11: 民族一路、天祥二路 | D11: 22.66824 | E11: 120.31702 | F11: 有
A12: S004401 | B12: 鼓山區 | C12: 中華一路與美術東五路 | D12: 22.65892 | E12: 120.29238 | F12: 有
A13: S004501 | B13: 鼓山區 | C13: 中華一路與美術東一路 | D13: 22.65604 | E13: 120.29223 | F13: 有
A14: S004601 | B14: 鼓山區 | C14: 中華一路與美術館路 | D14: 22.65469 | E14: 120.29217 | F14: 有
... A487: S094301 | B487: 前鎮區 | C487: 凱旋四路 瑞吉街 | D487: 22.5981 | E487: 120.3186 | F487: 有
A488: S094401 | C488: 旗津區-旗津二路與敦和街(南) | F488: 有
A489: S094501 | B489: 旗津區 | C489: 旗津區-旗津二路與敦和街(北) | D489: 22.57147 | E489: 120.29992 | F489: 有
A490: S094701 | B490: 旗津區 | C490: 旗津區-旗津二路與旗津二路195號 | D490: 22.57551 | E490: 120.29649 | F490: 有
A491: S094901 | B491: 三民區 | C491: 博愛一路、熱河一街 | D491: 22.64401 | E491: 120.30295 | F491: 有
A492: S095001 | B492: 旗津區 | C492: 旗津區-旗津二路與南汕巷 | D492: 22.58483 | E492: 120.28901 | F492: 有
A493: S095101 | B493: 三民區 | C493: 博愛一路、博仁街 | D493: 22.64661 | E493: 120.30312 | F493: 有
A494: S095201 | B494: 旗津區 | C494: 旗津區-旗津二路與旗津國中 | D494: 22.58832 | E494: 120.28595 | F494: 有
A495: S095301 | B495: 旗津區 | C495: 旗津區-旗津三路與旗港路 | D495: 22.58976 | E495: 120.28473 | F495: 有
A496: S095401 | B496: 三民區 | C496: 博愛一路、北平一街 | D496: 22.65016 | E496: 120.30346 | F496: 有
A497: S095501 | B497: 三民區 | C497: 同盟一路、博愛一路 | D497: 22.65195 | E497: 120.30365 | F497: 有
A498: S095601 | B498: 左營區 | C498: 博愛三路、新莊仔路(新莊一路) | D498: 22.67035 | E498: 120.30345 | F498: 有
A499: S095701 | B499: 旗津區 | C499: 旗津區-旗津三路與旗津三路62巷 | D499: 22.5969 | E499: 120.27888 | F499: 有
A500: S095801 | B500: 旗津區 | C500: 旗津區-旗津三路與海岸公園 | D500: 22.60255 | E500: 120.27482 | F500: 有
... A1943: S635001 | B1943: 前鎮區 | C1943: 前鎮街、鎮華街 | D1943: 22.59039 | E1943: 120.30729 | F1943: 有
A1944: S636201 | C1944: 高坪7路、高坪22路 | F1944: 有
A1945: S636301 | B1945: 小港區 | C1945: 高坪7路、高坪6街 | D1945: 22.54358 | E1945: 120.38122 | F1945: 有
A1946: S636501 | B1946: 小港區 | C1946: 高坪7路、榮唐公司 | D1946: 22.54733 | E1946: 120.38225 | F1946: 有
A1947: S636701 | B1947: 小港區 | C1947: 高坪7路、聯邦運輸 | D1947: 22.54861 | E1947: 120.38314 | F1947: 有
A1948: S637601 | B1948: 小港區 | C1948: 高坪23路、高坪二十五路(十九街) | D1948: 22.55773 | E1948: 120.38853 | F1948: 有
A1949: S637701 | B1949: 小港區 | C1949: 高坪23路、高坪151巷 | D1949: 22.5555 | E1949: 120.38881 | F1949: 有
A1950: S637901 | B1950: 小港區 | C1950: 高坪11路、高坪十六街 | D1950: 22.5484 | E1950: 120.38172 | F1950: 有
A1951: S638301 | B1951: 小港區 | C1951: 高坪11路、高坪五路 | D1951: 22.54198 | E1951: 120.38054 | F1951: 有
A1952: S638601 | B1952: 小港區 | C1952: 高坪18路、高坪二十三路 | D1952: 22.55341 | E1952: 120.38953 | F1952: 有
A1953: S639001 | B1953: 小港區 | C1953: 高坪35路、高坪十一路 | D1953: 22.55007 | E1953: 120.38333 | F1953: 有
A1954: S639301 | B1954: 小港區 | C1954: 高坪35路、高坪三十九街 | D1954: 22.55258 | E1954: 120.38181 | F1954: 有
...

Sheet 清冊(屏東縣)
A1: **填報號誌類型:非特種單閃號誌，三色運作及三色燈箱閃光運作皆請填報
A2: 號誌編號 | B2: 行政區 | C2: 號誌設置位置 | D2: 緯度 | E2: 經度 | F2: 通訊模組
A3: S000101 | B3: 屏東市 | C3: 台1線/縣道189線-大溪路 | D3: 22.650522 | E3: 120.45023 | F3: 有
A4: S000201 | B4: 屏東市 | C4: 台1線/建國路375巷 | D4: 22.654537 | E4: 120.46379 | F4: 有
A5: S000301 | B5: 屏東市 | C5: 台1線/清進路 | D5: 22.655374 | E5: 120.46604 | F5: 有
A6: S000401 | B6: 屏東市 | C6: 台1線/和生路三段 | D6: 22.655874 | E6: 120.46645 | F6: 有
A7: S000501 | B7: 屏東市 | C7: 台1線/和生路二段542巷 | D7: 22.654834 | E7: 120.47077 | F7: 有
A8: S000601 | B8: 屏東市 | C8: 台1線/崁頂巷 | D8: 22.654241 | E8: 120.47319 | F8: 有
A9: S000701 | B9: 屏東市 | C9: 台1線/武成街 | D9: 22.653653 | E9: 120.47563 | F9: 有
A10: S003001 | B10: 麟洛鄉 | C10: 台1線/永昌巷/永達巷 | D10: 22.652412 | E10: 120.52446 | F10: 有
A11: S003101 | B11: 麟洛鄉 | C11: 台1線/中華路/成功路 | D11: 22.65195 | E11: 120.52523 | F11: 有
A12: S003201 | B12: 麟洛鄉 | C12: 台1線/中正路/民權路 | D12: 22.651511 | E12: 120.52598 | F12: 有
A13: S003301 | B13: 麟洛鄉 | C13: 台1線/民族路 | D13: 22.650676 | E13: 120.52686 | F13: 有
A14: S003401 | B14: 麟洛鄉 | C14: 台1線/大同街 | D14: 22.64932 | E14: 120.52807 | F14: 有
... A131: S032701 | B131: 佳冬鄉 | C131: 台17線、羌園二號橋(先進汽車保養廠前) | D131: 22.424861 | E131: 120.53336 | F131: 有

Sheet 清冊(宜蘭縣)
A1: **填報號誌類型:非特種單閃號誌，三色運作及三色燈箱閃光運作皆請填報
A2: 號誌編號 | B2: 行政區 | C2: 號誌設置位置 | D2: 緯度 | E2: 經度 | F2: 通訊模組
A3: S065201 | B3: 礁溪鄉 | C3: 北宜路一段(台9)/青雲路一段(台2庚) | D3: 24.83848 | E3: 121.79073 | F3: 有
A4: S071801 | B4: 礁溪鄉 | C4: 礁溪路七段(台9)/礁溪路七段141巷 | D4: 24.83726 | E4: 121.78827 | F4: 有
A5: S071901 | B5: 礁溪鄉 | C5: 礁溪路七段(台9)/礁溪路七段87巷 | D5: 24.83655 | E5: 121.78594 | F5: 有
A6: S072001 | B6: 礁溪鄉 | C6: 礁溪路七段(台9)/白石腳路 | D6: 24.8359 | E6: 121.78337 | F6: 有
A7: S072101 | B7: 礁溪鄉 | C7: 礁溪路六段(台9)/礁溪路六段133巷 | D7: 24.83508 | E7: 121.7815 | F7: 有
A8: S073601 | B8: 礁溪鄉 | C8: 礁溪路三段(台9)/十六結路 | D8: 24.80892 | E8: 121.76684 | F8: 有
A9: S070701 | B9: 礁溪鄉 | C9: 縣191/踏踏路(宜6) | D9: 24.796271 | E9: 121.78193 | F9: 有
A10: S070501 | B10: 礁溪鄉 | C10: 縣191/淇武蘭路 | D10: 24.812541 | E10: 121.78108 | F10: 有
A11: S066801 | B11: 礁溪鄉 | C11: 縣191/興農路 | D11: 24.81665 | E11: 121.78154 | F11: 有
A12: S070401 | B12: 礁溪鄉 | C12: 縣191/興農路291巷 | D12: 24.818226 | E12: 121.78186 | F12: 有
A13: S070301 | B13: 礁溪鄉 | C13: 縣道191/奇立丹路 | D13: 24.819949 | E13: 121.78282 | F13: 有
A14: S066701 | B14: 礁溪鄉 | C14: 縣191/奇立丹路(北上) | D14: 24.82116 | E14: 121.78421 | F14: 有
... A45: S005401 | B45: 宜蘭市 | C45: 宜興路一段/校舍路/復興路 | D45: 24.75017 | E45: 121.75574 | F45: 有

Sheet 清冊(花蓮縣)
A1: **填報號誌類型:非特種單閃號誌，三色運作及三色燈箱閃光運作皆請填報
A2: 號誌編號 | B2: 行政區 | C2: 號誌設置位置 | D2: 緯度 | E2: 經度 | F2: 通訊模組
A3: G035 | B3: 新城鄉 | C3: 2.PFI 新城鄉台9-187K+100(嘉南-嘉新-華西路口) | D3: 24.007671 | E3: 121.615697 | F3: 有
A4: G039 | B4: 新城鄉 | C4: 新城鄉台9-186K+950(嘉新路-海星中學) | D4: 24.007261 | E4: 121.613977 | F4: 有
A5: G044 | B5: 新城鄉 | C5: 新城鄉台9-186K+740(嘉新路-嘉南一街) | D5: 24.006837 | E5: 121.612934 | F5: 有
A6: G072 | B6: 花蓮市 | C6: 花蓮市國民路-國盛七街口(防汛道路) | D6: 23.997481 | E6: 121.611170 | F6: 有
A7: G245 | B7: 吉安鄉 | C7: 吉安鄉台9丙-1K+900(中華路二段-宜昌一街) | D7: 23.974050 | E7: 121.587692 | F7: 有
A8: HL0116 | B8: 玉里鎮 | C8: 玉里鎮仁愛路二段-民權街(慈濟醫院前) | D8: 23.334964 | E8: 121.318888 | F8: 有
A9: HL0121 | B9: 吉安鄉 | C9: 中央路二段-吉昌二街 | D9: 23.967267 | E9: 121.568639 | F9: 有
A10: HL0128 | B10: 花蓮市 | C10: 花蓮市-公園路-三民街 | D10: 23.977271 | E10: 121.611208 | F10: 有
A11: HL0135 | B11: 吉安鄉 | C11: 吉安鄉台9丙-8K+444(吉安路六段)-干城二街 | D11: 23.945048 | E11: 121.547617 | F11: 有
A12: HL0137 | B12: 吉安鄉 | C12: 吉安鄉中央路二段-中央路二段171巷 | D12: 23.972374 | E12: 121.572151 | F12: 有
A13: HL0140 | B13: 吉安鄉 | C13: 吉安鄉慶豐十一街-慶北三街 | D13: 23.982764 | E13: 121.566134 | F13: 有
... A130: R060 | B130: 壽豐鄉 | C130: 壽豐鄉台11-6K+450 | D130: 23.925467 | E130: 121.604284 | F130: 有

Sheet 清冊(臺東縣)
A1: **填報號誌類型:非特種單閃號誌，三色運作及三色燈箱閃光運作皆請填報
A2: 號誌編號 | B2: 行政區 | C2: 號誌設置位置 | D2: 緯度 | E2: 經度 | F2: 通訊模組
A3: S100011 | B3: 臺東市 | C3: 更生路/中山路 | D3: 22.755819 | E3: 121.15107 | F3: 有
A4: S100021 | B4: 臺東市 | C4: 更生路/五權街 | D4: 22.757148 | E4: 121.14988 | F4: 有
A5: S100031 | B5: 臺東市 | C5: 更生路/博愛路 | D5: 22.75785 | E5: 121.14928 | F5: 有
A6: S100201 | B6: 臺東市 | C6: 正氣北路/漢中街 | D6: 22.755828 | E6: 121.13884 | F6: 有
A7: S100211 | B7: 臺東市 | C7: 新生路/中山路 | D7: 22.752647 | E7: 121.14811 | F7: 有
A8: S100221 | B8: 臺東市 | C8: 新生路/博愛路 | D8: 22.754408 | E8: 121.14595 | F8: 有
A9: S100231 | B9: 臺東市 | C9: 新生路/南京路 | D9: 22.755318 | E9: 121.14502 | F9: 有
A10: S100241 | B10: 臺東市 | C10: 新生路/四維路三段 | D10: 22.763053 | E10: 121.13647 | F10: 有
A11: S100251 | B11: 臺東市 | C11: 中興路一段/新生路 | D11: 22.766141 | E11: 121.1334 | F11: 有
A12: S100261 | B12: 卑南鄉 | C12: 忠孝路/文泰路 | D12: 22.857243 | E12: 121.09225 | F12: 有
A13: S100271 | B13: 卑南鄉 | C13: 臺9乙線/賓朗路 | D13: 22.800874 | E13: 121.09472 | F13: 有
A14: S100281 | B14: 臺東市 | C14: 新生路/光明路 | D14: 22.7521 | E14: 121.14869 | F14: 有
... A118: S101551 | B118: 臺東市 | C118: 中興路二段/東糖街 | D118: 22.76701 | E118: 121.13009 | F118: 有

Sheet 清冊(澎湖縣)
A1: **填報號誌類型:非特種單閃號誌，三色運作及三色燈箱閃光運作皆請填報
A2: 號誌編號 | B2: 行政區 | C2: 號誌設置位置 | D2: 緯度 | E2: 經度 | F2: 通訊模組
A3: 1 | B3: 馬公市 | C3: 濟公廟前 | D3: 23.546719 | E3: 119.607868 | F3: 有
A4: 2 | B4: 馬公市 | C4: 鐵線社區路口 | D4: 23.533788 | E4: 119.6024 | F4: 有
A5: 3 | B5: 馬公市 | C5: 鐵線、鎖港路口 | D5: 23.531134 | E5: 119.60087 | F5: 有
A6: 4 | B6: 馬公市 | C6: 五德國小路口 | D6: 23.527174 | E6: 119.590801 | F6: 有
A7: 12 | B7: 湖西鄉 | C7: 西溪國小路口 | D7: 23.582072 | E7: 119.64263 | F7: 有
A8: 13 | B8: 湖西鄉 | C8: 湖西國中路口 | D8: 23.583624 | E8: 119.65347 | F8: 有
A9: 14 | B9: 湖西鄉 | C9: 湖西分駐所前路口 | D9: 23.584559 | E9: 119.658372 | F9: 有
A10: 15 | B10: 湖西鄉 | C10: 縣道202線與澎15號道 | D10: 23.584741 | E10: 119.660146 | F10: 有
A11: 16 | B11: 湖西鄉 | C11: 縣道202線湖西幼稚園岔路口 | D11: 23.584582 | E11: 119.658411 | F11: 有
A12: 17 | B12: 湖西鄉 | C12: 縣道202線南寮村岔路口 | D12: 23.583622 | E12: 119.66648 | F12: 有
A13: 18 | B13: 馬公市 | C13: 中正、中山路口 | D13: 23.563524 | E13: 119.56512 | F13: 有
A14: 19 | B14: 馬公市 | C14: 中正、仁愛路口 | D14: 23.565561 | E14: 119.56533 | F14: 有
A15: 20 | B15: 馬公市 | C15: 中正、民生路口 | D15: 23.567654 | E15: 119.565529 | F15: 有
A16: 21 | B16: 馬公市 | C16: 中正、樹德路口 | D16: 23.568902 | E16: 119.56637 | F16: 有
A17: 22 | B17: 馬公市 | C17: 中正、治平路口 | D17: 23.569638 | E17: 119.566411 | F17: 有
A18: 30 | B18: 馬公市 | C18: 中華、文化局路口 | D18: 23.571712 | E18: 119.57849 | F18: 有
A19: 31 | B19: 馬公市 | C19: 馬公高中路口 | D19: 23.570875 | E19: 119.58043 | F19: 有
A20: 32 | B20: 馬公市 | C20: 中華、六合路口 | D20: 23.570023 | E20: 119.58187 | F20: 有
A21: 33 | B21: 馬公市 | C21: 簡易法庭前路口 | D21: 23.569791 | E21: 119.58248 | F21: 有
A22: 34 | B22: 馬公市 | C22: 台電營業處 | D22: 23.569411 | E22: 119.58561 | F22: 有
A23: 35 | B23: 馬公市 | C23: 聯富保養廠 | D23: 23.569133 | E23: 119.58654 | F23: 有
A24: 36 | B24: 馬公市 | C24: 釣漁人量販前路口 | D24: 23.569002 | E24: 119.58746 | F24: 有
A25: 37 | B25: 馬公市 | C25: 馬公都市計畫20-3道 | D25: 23.564965 | E25: 119.58725 | F25: 有
A26: 38 | B26: 馬公市 | C26: 文東加油站前路口 | D26: 23.568864 | E26: 119.59385 | F26: 有
A27: 39 | B27: 馬公市 | C27: 縣道203、202線岔路口 | D27: 23.568989 | E27: 119.59847 | F27: 有
A28: 40 | B28: 馬公市 | C28: 安宅社區前岔路口 | D28: 23.575654 | E28: 119.60217 | F28: 有
A29: 41 | B29: 湖西鄉 | C29: 許家村前路口 | D29: 23.5851 | E29: 119.60832 | F29: 有
... A148: 183 | B148: 白沙鄉 | C148: 澎8號道與澎7號道岔路口 | D148: 23.65582 | E148: 119.58574 | F148: 有

Sheet 清冊(金門縣)
A1: **填報號誌類型:非特種單閃號誌，三色運作及三色燈箱閃光運作皆請填報
A2: 號誌編號 | B2: 行政區 | C2: 號誌設置位置 | D2: 緯度 | E2: 經度 | F2: 通訊模組
A3: S001401 | B3: 金沙鎮 | C3: 環島東路一段/陽沙路 | D3: 24.47740 | E3: 118.42860 | F3: 無
A4: S001501 | B4: 金沙鎮 | C4: 環島北路四段/成功路 | D4: 24.49050 | E4: 118.41054 | F4: 無
A5: S002001 | B5: 金城鎮 | C5: 西海路三段/泰仰路 | D5: 24.41713 | E5: 118.30820 | F5: 無
A6: S002101 | B6: 金城鎮 | C6: 金豐路/新豐路 | D6: 24.41706 | E6: 118.30054 | F6: 無
A7: S002201 | B7: 金城鎮 | C7: 浯江北堤路(迴龍宮) | D7: 24.42964 | E7: 118.31948 | F7: 無
A8: S002301 | B8: 金城鎮 | C8: 西海路二段/金豐路 | D8: 24.41447 | E8: 118.30445 | F8: 無
A9: S002401 | B9: 金湖鎮 | C9: 伯玉路三段/中山路 | D9: 24.44610 | E9: 118.36490 | F9: 無
A10: S002501 | B10: 金湖鎮 | C10: 伯玉路(瓊林圓環) | D10: 24.44684 | E10: 118.37667 | F10: 無
A11: S003501 | B11: 金湖鎮 | C11: 環島南路四段/塔后路 | D11: 24.43783 | E11: 118.40688 | F11: 無
A12: S003601 | B12: 金湖鎮 | C12: 環島南路四段/夏興路 | D12: 24.43913 | E12: 118.39464 | F12: 無
A13: S003701 | B13: 金湖鎮 | C13: 環島北路三段(瓊林風獅爺) | D13: 24.45674 | E13: 118.37380 | F13: 無
A14: S003801 | B14: 金湖鎮 | C14: 環島南路五段/市港路 | D14: 24.43604 | E14: 118.40981 | F14: 無
A15: S003901 | B15: 金湖鎮 | C15: 太湖路二段3巷/市港六路 | D15: 24.43799 | E15: 118.41782 | F15: 無
A16: S004001 | B16: 金寧鄉 | C16: 桃園路/林湖路 | D16: 24.43251 | E16: 118.33054 | F16: 無
A17: S004101 | B17: 金寧鄉 | C17: 環島南路一段/東湖路 | D17: 24.42291 | E17: 118.33863 | F17: 無
... A23: S005101 | B23: 金寧鄉 | C23: 桃園路/酒廠前路段 | D23: 24.431731 | E23: 118.34404 | F23: 無
A24: 單閃 | B24: 金沙鎮 | C24: 環島東路/高陽路 | F24: 無
A25: 單閃 | B25: 金沙鎮 | C25: 高陽路/蔡厝路 | F25: 無
A26: 單閃 | B26: 金沙鎮 | C26: 環島北路三段/環中路 | F26: 無
A27: 單閃 | B27: 金城鎮 | C27: 西海路三段/賢城路 | F27: 無
A28: 單閃 | B28: 金城鎮 | C28: 環島西路一段/賢城路 | F28: 無
A29: 單閃 | B29: 金寧鄉 | C29: 伯玉路二段(國家公園) | F29: 無
A30: 單閃 | B30: 金寧鄉 | C30: 伯玉路一段 | F30: 無
A31: 單閃 | B31: 金寧鄉 | C31: 伯玉路(東林修車廠) | F31: 無
A32: 單閃 | B32: 金寧鄉 | C32: 伯玉路/后盤山路 | F32: 無
A33: 單閃 | B33: 金寧鄉 | C33: 環島西路二段/瓊安路 | F33: 無
A34: 單閃 | B34: 金寧鄉 | C34: 環島北路二段/司法大道 | F34: 無
A35: 三色閃光 | B35: 金沙鎮 | C35: 環島東路一段(金沙國小) | F35: 無
... A38: 三色閃光 | B38: 金寧鄉 | C38: 環島南路三段/桃園路(地下道前) | F38: 無

Sheet 其他縣市未提交原因
A1: 項次 | B1: 縣市 | C1: 回覆內容
A2: 1 | B2: 嘉義縣 | C2: 無通訊模組
A3: 2 | B3: 連江縣 | C3: 本縣無設置號誌
A4: 3

Sheet 欄位填寫說明
B1: 說明
A2: 號誌編號 | B2: 縣市簡碼-縣市自訂號誌編碼
A3: 行政區 | B3: 縣市三級行政區
A4: 號誌設置位置 | B4: 號誌所在路口
A5: 緯度 | B5: 所在路口範圍內之緯度座標(計算至小數點後五位)
A6: 經度 | B6: 所在路口範圍內之經度座標(計算至小數點後五位)
A7: 通訊模組 | B7: 有無安裝通訊模組(有安裝但斷線仍為【有】)
